#

## `try ... catch ... finally`

```js
var r1, r2, s = null;
try {
    r1 = s.length; // 此处应产生错误
    r2 = 100; // 该语句不会执行
} catch (e) {
    console.log('出错了：' + e);
} finally {
    console.log('finally');
}
console.log('r1 = ' + r1); // r1应为undefined
console.log('r2 = ' + r2); // r2应为undefined
```

## 错误类型

JavaScript有一个标准的`Error`对象表示错误，还有从`Error`派生的`TypeError`、`ReferenceError`等错误对象。我们在处理错误时，可以通过`catch(e)`捕获的变量e访问错误对象：

```js
try {
    ...
} catch (e) {
    if (e instanceof TypeError) {
        alert('Type error!');
    } else if (e instanceof Error) {
        alert(e.message);
    } else {
        alert('Error: ' + e);
    }
}
```

## 抛出错误

`throw new Error('输入错误');`

## 错误传播

如果在一个函数内部发生了错误，它自身没有捕获，错误就会被抛到外层调用函数，如果外层函数也没有捕获，该错误会一直沿着函数调用链向上抛出，直到被JavaScript引擎捕获，代码终止执行。

## 异步错误处理

```js
// 无效
function printTime() {
    throw new Error();
}

try {
    setTimeout(printTime, 1000);
    console.log('done');
} catch (e) {
    console.log('error');
}
```